Workbook

Sheet CAPA
A4: REPÚBLICA DE ANGOLA
A5: MINISTÉRIO DA EDUCAÇÃO
A6: GABINETE DE ESTUDOS, PLANEAMENTO E ESTATÍSTICA
A7: DEPARTAMENTO DE ESTUDOS E ESTATÍSTICA
A10: INSTRUMENTO COMPLEMENTAR DO SIGE 2024/2025
A15: PROVÍNCIA:
A16: MUNICÍPIO:
A23: OBSERVAÇÕES GERAIS
B24: EDUCAÇÃO PRÉ-ESCOLAR | E24: INSTRUÇÕES DE PREENCHIMENTO: 1. Por definição, todos os campos estarão preenchidos com 0; 2. Sempre colar dados provenientes de outros instrumentos, deve-se colar como número/valores para não remover a formatação da célula; 3. Não alterar a estrutura de colunas, linhas e fórmulas automáticas; 4. Distinguir sempre MF (Masculino + Feminino) de F (Feminino); 5. O preenchimento fidedigno é de carácter obrigatório nos termos da legislação em vigor.
B25: ENSINO PRIMÁRIO
B26: ENSINO SECUNDÁRIO I CICLO
B27: ENSINO SECUNDÁRIO II CICLO
B28: EDUCAÇÃO ESPECIAL
B29: EDUCAÇÃO DE JOVENS E ADULTOS
B30: COMPLEXO ESCOLAR
B31: TOTAL
A33: Data de entrega pelo GEPE: | C33: 23 de Setembro de 2025 | F33: Data de entrega ao GPE/SPE pela DME/SME:

Sheet 1 - ALUNOS MATRICULADOS
A2: SECÇÃO 1 - DADOS ESTATÍSTICOS SOBRE ALUNOS MATRICULADOS
A5: 1. EDUCAÇÃO PRÉ-ESCOLAR
A6: TABELA 1.1 – Crianças matriculadas nas Creches, Jardins de Infância, Centros Infantis, Centros Infantis Comunitários e Centros de Educação Comunitária
A8: ETAPA | B8: NATUREZA DE ENSINO | C8: TOTAL | E8: 3 Meses aos 3 anos | G8: 3 Anos | I8: 4 Anos | K8: 5 Anos | M8: 6 Anos | O8: Mais de 6 Anos | R8: OBSERVAÇÕES
C9: Total (MF) | D9: Total (F) | E9: MF | F9: F | G9: MF | H9: F | I9: MF | J9: F | K9: MF | L9: F | M9: MF | N9: F | O9: MF | P9: F
A10: CRECHE | B10: PÚBLICA | C10: =SUM(E10,G10,I10,K10,M10,O10) | D10: =SUM(F10,H10,J10,L10,N10,P10) | E10: 0 | F10: 0 | G10: 0 | H10: 0 | I10: 0 | J10: 0 | K10: 0 | L10: 0 | M10: 0 | N10: 0 | O10: 0 | P10: 0
B11: PÚBLICO-PRIVADA | C11: =SUM(E11,G11,I11,K11,M11,O11) | D11: =SUM(F11,H11,J11,L11,N11,P11) | E11: 0 | F11: 0 | G11: 0 | H11: 0 | I11: 0 | J11: 0 | K11: 0 | L11: 0 | M11: 0 | N11: 0 | O11: 0 | P11: 0
B12: PRIVADA | C12: =SUM(E12,G12,I12,K12,M12,O12) | D12: =SUM(F12,H12,J12,L12,N12,P12) | E12: 0 | F12: 0 | G12: 0 | H12: 0 | I12: 0 | J12: 0 | K12: 0 | L12: 0 | M12: 0 | N12: 0 | O12: 0 | P12: 0
A13: JARDIM DE INFANCIA1 | B13: PÚBLICA | C13: =SUM(E13,G13,I13,K13,M13,O13) | D13: =SUM(F13,H13,J13,L13,N13,P13) | E13: 0 | F13: 0 | G13: 0 | H13: 0 | I13: 0 | J13: 0 | K13: 0 | L13: 0 | M13: 0 | N13: 0 | O13: 0 | P13: 0
B14: PÚBLICO-PRIVADA | C14: =SUM(E14,G14,I14,K14,M14,O14) | D14: =SUM(F14,H14,J14,L14,N14,P14) | E14: 0 | F14: 0 | G14: 0 | H14: 0 | I14: 0 | J14: 0 | K14: 0 | L14: 0 | M14: 0 | N14: 0 | O14: 0 | P14: 0
B15: PRIVADA | C15: =SUM(E15,G15,I15,K15,M15,O15) | D15: =SUM(F15,H15,J15,L15,N15,P15) | E15: 0 | F15: 0 | G15: 0 | H15: 0 | I15: 0 | J15: 0 | K15: 0 | L15: 0 | M15: 0 | N15: 0 | O15: 0 | P15: 0
A16: JARDIM DE INFANCIA2 | B16: PÚBLICA | C16: =SUM(E16,G16,I16,K16,M16,O16) | D16: =SUM(F16,H16,J16,L16,N16,P16) | E16: 0 | F16: 0 | G16: 0 | H16: 0 | I16: 0 | J16: 0 | K16: 0 | L16: 0 | M16: 0 | N16: 0 | O16: 0 | P16: 0
B17: PÚBLICO-PRIVADA | C17: =SUM(E17,G17,I17,K17,M17,O17) | D17: =SUM(F17,H17,J17,L17,N17,P17) | E17: 0 | F17: 0 | G17: 0 | H17: 0 | I17: 0 | J17: 0 | K17: 0 | L17: 0 | M17: 0 | N17: 0 | O17: 0 | P17: 0
B18: PRIVADA | C18: =SUM(E18,G18,I18,K18,M18,O18) | D18: =SUM(F18,H18,J18,L18,N18,P18) | E18: 0 | F18: 0 | G18: 0 | H18: 0 | I18: 0 | J18: 0 | K18: 0 | L18: 0 | M18: 0 | N18: 0 | O18: 0 | P18: 0
A19: CENTROS INFANTIS | B19: PÚBLICA | C19: =SUM(E19,G19,I19,K19,M19,O19) | D19: =SUM(F19,H19,J19,L19,N19,P19) | E19: 0 | F19: 0 | G19: 0 | H19: 0 | I19: 0 | J19: 0 | K19: 0 | L19: 0 | M19: 0 | N19: 0 | O19: 0 | P19: 0
B20: PÚBLICO-PRIVADA | C20: =SUM(E20,G20,I20,K20,M20,O20) | D20: =SUM(F20,H20,J20,L20,N20,P20) | E20: 0 | F20: 0 | G20: 0 | H20: 0 | I20: 0 | J20: 0 | K20: 0 | L20: 0 | M20: 0 | N20: 0 | O20: 0 | P20: 0
B21: PRIVADA | C21: =SUM(E21,G21,I21,K21,M21,O21) | D21: =SUM(F21,H21,J21,L21,N21,P21) | E21: 0 | F21: 0 | G21: 0 | H21: 0 | I21: 0 | J21: 0 | K21: 0 | L21: 0 | M21: 0 | N21: 0 | O21: 0 | P21: 0
A22: CENTROS INFANTIS COMUNITÁRIOS | B22: PÚBLICA | C22: =SUM(E22,G22,I22,K22,M22,O22) | D22: =SUM(F22,H22,J22,L22,N22,P22) | E22: 0 | F22: 0 | G22: 0 | H22: 0 | I22: 0 | J22: 0 | K22: 0 | L22: 0 | M22: 0 | N22: 0 | O22: 0 | P22: 0
B23: PÚBLICO-PRIVADA | C23: =SUM(E23,G23,I23,K23,M23,O23) | D23: =SUM(F23,H23,J23,L23,N23,P23) | E23: 0 | F23: 0 | G23: 0 | H23: 0 | I23: 0 | J23: 0 | K23: 0 | L23: 0 | M23: 0 | N23: 0 | O23: 0 | P23: 0
B24: PRIVADA | C24: =SUM(E24,G24,I24,K24,M24,O24) | D24: =SUM(F24,H24,J24,L24,N24,P24) | E24: 0 | F24: 0 | G24: 0 | H24: 0 | I24: 0 | J24: 0 | K24: 0 | L24: 0 | M24: 0 | N24: 0 | O24: 0 | P24: 0
A25: CENTROS DE EDUCAÇÃO COMUNITÁRIA | B25: PÚBLICA | C25: =SUM(E25,G25,I25,K25,M25,O25) | D25: =SUM(F25,H25,J25,L25,N25,P25) | E25: 0 | F25: 0 | G25: 0 | H25: 0 | I25: 0 | J25: 0 | K25: 0 | L25: 0 | M25: 0 | N25: 0 | O25: 0 | P25: 0
B26: PÚBLICO-PRIVADA | C26: =SUM(E26,G26,I26,K26,M26,O26) | D26: =SUM(F26,H26,J26,L26,N26,P26) | E26: 0 | F26: 0 | G26: 0 | H26: 0 | I26: 0 | J26: 0 | K26: 0 | L26: 0 | M26: 0 | N26: 0 | O26: 0 | P26: 0
B27: PRIVADA | C27: =SUM(E27,G27,I27,K27,M27,O27) | D27: =SUM(F27,H27,J27,L27,N27,P27) | E27: 0 | F27: 0 | G27: 0 | H27: 0 | I27: 0 | J27: 0 | K27: 0 | L27: 0 | M27: 0 | N27: 0 | O27: 0 | P27: 0
A28: TOTAL | B28: PÚBLICA | C28: =SUM(C10,C13,C16,C19,C22,C25) | D28: =SUM(D10,D13,D16,D19,D22,D25) | E28: =SUM(E10,E13,E16,E19,E22,E25) | F28: =SUM(F10,F13,F16,F19,F22,F25) | G28: =SUM(G10,G13,G16,G19,G22,G25) | H28: =SUM(H10,H13,H16,H19,H22,H25) | I28: =SUM(I10,I13,I16,I19,I22,I25) | J28: =SUM(J10,J13,J16,J19,J22,J25) | ... P28: =SUM(P10,P13,P16,P19,P22,P25)
A29: TOTAL | B29: PÚBLICO-PRIVADA | C29: =SUM(C11,C14,C17,C20,C23,C26) | D29: =SUM(D11,D14,D17,D20,D23,D26) | E29: =SUM(E11,E14,E17,E20,E23,E26) | F29: =SUM(F11,F14,F17,F20,F23,F26) | G29: =SUM(G11,G14,G17,G20,G23,G26) | H29: =SUM(H11,H14,H17,H20,H23,H26) | I29: =SUM(I11,I14,I17,I20,I23,I26) | J29: =SUM(J11,J14,J17,J20,J23,J26) | ... P29: =SUM(P11,P14,P17,P20,P23,P26)
A30: TOTAL | B30: PRIVADA | C30: =SUM(C12,C15,C18,C21,C24,C27) | D30: =SUM(D12,D15,D18,D21,D24,D27) | E30: =SUM(E12,E15,E18,E21,E24,E27) | F30: =SUM(F12,F15,F18,F21,F24,F27) | G30: =SUM(G12,G15,G18,G21,G24,G27) | H30: =SUM(H12,H15,H18,H21,H24,H27) | I30: =SUM(I12,I15,I18,I21,I24,I27) | J30: =SUM(J12,J15,J18,J21,J24,J27) | ... P30: =SUM(P12,P15,P18,P21,P24,P27)
A31: TOTAL GERAL | B31: TODAS | C31: =SUM(C28:C30) | D31: =SUM(D28:D30) | E31: =SUM(E28:E30) | F31: =SUM(F28:F30) | G31: =SUM(G28:G30) | H31: =SUM(H28:H30) | I31: =SUM(I28:I30) | J31: =SUM(J28:J30) | ... P31: =SUM(P28:P30)
A34: TABELA 1.2 – Alunos matriculados na Classe de Iniciação nas escolas
A35: CLASSE | B35: NATUREZA DE ENSINO | C35: TOTAL | E35: 5 Anos | G35: 6 Anos | I35: 7 Anos | K35: 8 Anos | M35: 9 Anos | O35: 10 Anos | Q35: 11 Anos | S35: 12 Anos | U35: 13 Anos | W35: Mais de 13 Anos
C36: Total (MF) | D36: Total (F) | E36: MF | F36: F | G36: MF | H36: F | I36: MF | J36: F | K36: MF | L36: F | M36: MF | N36: F | O36: MF | P36: F | Q36: MF | R36: F | S36: MF | T36: F | U36: MF | V36: F | W36: MF | X36: F
A37: INICIAÇÃO | B37: PÚBLICA | C37: =SUM(E37,G37,I37,K37,M37,O37,Q37,S37,U37,W37) | D37: =SUM(F37,H37,J37,L37,N37,P37,R37,T37,V37,X37) | E37: 0 | F37: 0 | G37: 0 | H37: 0 | I37: 0 | J37: 0 | K37: 0 | L37: 0 | M37: 0 | N37: 0 | O37: 0 | P37: 0 | Q37: 0 | R37: 0 | S37: 0 | T37: 0 | U37: 0 | V37: 0 | W37: 0 | X37: 0
B38: PÚBLICO-PRIVADA | C38: =SUM(E38,G38,I38,K38,M38,O38,Q38,S38,U38,W38) | D38: =SUM(F38,H38,J38,L38,N38,P38,R38,T38,V38,X38) | E38: 0 | F38: 0 | G38: 0 | H38: 0 | I38: 0 | J38: 0 | K38: 0 | L38: 0 | M38: 0 | N38: 0 | O38: 0 | P38: 0 | Q38: 0 | R38: 0 | S38: 0 | T38: 0 | U38: 0 | V38: 0 | W38: 0 | X38: 0
B39: PRIVADA | C39: =SUM(E39,G39,I39,K39,M39,O39,Q39,S39,U39,W39) | D39: =SUM(F39,H39,J39,L39,N39,P39,R39,T39,V39,X39) | E39: 0 | F39: 0 | G39: 0 | H39: 0 | I39: 0 | J39: 0 | K39: 0 | L39: 0 | M39: 0 | N39: 0 | O39: 0 | P39: 0 | Q39: 0 | R39: 0 | S39: 0 | T39: 0 | U39: 0 | V39: 0 | W39: 0 | X39: 0
A40: TOTAL | B40: TODAS | C40: =SUM(C37:C39) | D40: =SUM(D37:D39) | E40: =SUM(E37:E39) | F40: =SUM(F37:F39) | G40: =SUM(G37:G39) | H40: =SUM(H37:H39) | I40: =SUM(I37:I39) | J40: =SUM(J37:J39) | ... X40: =SUM(X37:X39)
A42: TABELA 1.3 – Alunos com deficiência em escolas específicas de Ensino Especial (Sensorial / Iniciação)
A44: ETAPA | B44: NATUREZA DE ENSINO | C44: TOTAL | E44: Auditiva | G44: Intelectual | I44: Visual | K44: Surdo-Cegueira | M44: Múltipla | O44: Físico Motora | Q44: Espectro-Autista | S44: Altas Habilidades
C45: Total (MF) | D45: Total (F) | E45: MF | F45: F | G45: MF | H45: F | I45: MF | J45: F | K45: MF | L45: F | M45: MF | N45: F | O45: MF | P45: F | Q45: MF | R45: F | S45: MF | T45: F
A46: EDUCAÇÃO ESPECIAL | B46: PÚBLICA | C46: =SUM(E46,G46,I46,K46,M46,O46,Q46,S46) | D46: =SUM(F46,H46,J46,L46,N46,P46,R46,T46) | E46: 0 | F46: 0 | G46: 0 | H46: 0 | I46: 0 | J46: 0 | K46: 0 | L46: 0 | M46: 0 | N46: 0 | O46: 0 | P46: 0 | Q46: 0 | R46: 0 | S46: 0 | T46: 0
B47: PÚBLICO-PRIVADA | C47: =SUM(E47,G47,I47,K47,M47,O47,Q47,S47) | D47: =SUM(F47,H47,J47,L47,N47,P47,R47,T47) | E47: 0 | F47: 0 | G47: 0 | H47: 0 | I47: 0 | J47: 0 | K47: 0 | L47: 0 | M47: 0 | N47: 0 | O47: 0 | P47: 0 | Q47: 0 | R47: 0 | S47: 0 | T47: 0
B48: PRIVADA | C48: =SUM(E48,G48,I48,K48,M48,O48,Q48,S48) | D48: =SUM(F48,H48,J48,L48,N48,P48,R48,T48) | E48: 0 | F48: 0 | G48: 0 | H48: 0 | I48: 0 | J48: 0 | K48: 0 | L48: 0 | M48: 0 | N48: 0 | O48: 0 | P48: 0 | Q48: 0 | R48: 0 | S48: 0 | T48: 0
...

Sheet 2 - PESSOAL_DOCENTE
A2: SECÇÃO 2 - DADOS ESTATÍSTICOS SOBRE PESSOAL DOCENTE EM EXERCÍCIO
A4: TABELA 2.1 – Pessoal Docente na Educação Pré-Escolar
A5: NATUREZA DA ESCOLA | B5: CATEGORIA / FUNÇÃO | C5: TOTAL DE DOCENTES | E5: Mestrado / Doutoramento | G5: Licenciatura em Ensino | I5: Outras Licenciaturas | K5: Bacharelato | M5: Técnico Médio Pedagógico | O5: Outros Técnicos Médios
C6: Total (MF) | D6: Total (F) | E6: MF | F6: F | G6: MF | H6: F | I6: MF | J6: F | K6: MF | L6: F | M6: MF | N6: F | O6: MF | P6: F
A7: PÚBLICA | B7: Educadores / Professores Titulares | C7: =SUM(E7,G7,I7,K7,M7,O7) | D7: =SUM(F7,H7,J7,L7,N7,P7) | E7: 0 | F7: 0 | G7: 0 | H7: 0 | I7: 0 | J7: 0 | K7: 0 | L7: 0 | M7: 0 | N7: 0 | O7: 0 | P7: 0
B8: Professores Coadjuvantes | C8: =SUM(E8,G8,I8,K8,M8,O8) | D8: =SUM(F8,H8,J8,L8,N8,P8) | E8: 0 | F8: 0 | G8: 0 | H8: 0 | I8: 0 | J8: 0 | K8: 0 | L8: 0 | M8: 0 | N8: 0 | O8: 0 | P8: 0
B9: Professores Estagiários | C9: =SUM(E9,G9,I9,K9,M9,O9) | D9: =SUM(F9,H9,J9,L9,N9,P9) | E9: 0 | F9: 0 | G9: 0 | H9: 0 | I9: 0 | J9: 0 | K9: 0 | L9: 0 | M9: 0 | N9: 0 | O9: 0 | P9: 0
A10: SUBTOTAL | B10: PÚBLICA | C10: =SUM(C7:C9) | D10: =SUM(D7:D9) | E10: =SUM(E7:E9) | F10: =SUM(F7:F9) | G10: =SUM(G7:G9) | H10: =SUM(H7:H9) | I10: =SUM(I7:I9) | J10: =SUM(J7:J9) | ... P10: =SUM(P7:P9)
A11: PÚBLICO-PRIVADA | B11: Educadores / Professores Titulares | C11: =SUM(E11,G11,I11,K11,M11,O11) | D11: =SUM(F11,H11,J11,L11,N11,P11) | E11: 0 | F11: 0 | G11: 0 | H11: 0 | I11: 0 | J11: 0 | K11: 0 | L11: 0 | M11: 0 | N11: 0 | O11: 0 | P11: 0
B12: Professores Coadjuvantes | C12: =SUM(E12,G12,I12,K12,M12,O12) | D12: =SUM(F12,H12,J12,L12,N12,P12) | E12: 0 | F12: 0 | G12: 0 | H12: 0 | I12: 0 | J12: 0 | K12: 0 | L12: 0 | M12: 0 | N12: 0 | O12: 0 | P12: 0
B13: Professores Estagiários | C13: =SUM(E13,G13,I13,K13,M13,O13) | D13: =SUM(F13,H13,J13,L13,N13,P13) | E13: 0 | F13: 0 | G13: 0 | H13: 0 | I13: 0 | J13: 0 | K13: 0 | L13: 0 | M13: 0 | N13: 0 | O13: 0 | P13: 0
A14: SUBTOTAL | B14: PÚBLICO-PRIVADA | C14: =SUM(C11:C13) | D14: =SUM(D11:D13) | E14: =SUM(E11:E13) | F14: =SUM(F11:F13) | G14: =SUM(G11:G13) | H14: =SUM(H11:H13) | I14: =SUM(I11:I13) | J14: =SUM(J11:J13) | ... P14: =SUM(P11:P13)
A15: PRIVADA | B15: Educadores / Professores Titulares | C15: =SUM(E15,G15,I15,K15,M15,O15) | D15: =SUM(F15,H15,J15,L15,N15,P15) | E15: 0 | F15: 0 | G15: 0 | H15: 0 | I15: 0 | J15: 0 | K15: 0 | L15: 0 | M15: 0 | N15: 0 | O15: 0 | P15: 0
B16: Professores Coadjuvantes | C16: =SUM(E16,G16,I16,K16,M16,O16) | D16: =SUM(F16,H16,J16,L16,N16,P16) | E16: 0 | F16: 0 | G16: 0 | H16: 0 | I16: 0 | J16: 0 | K16: 0 | L16: 0 | M16: 0 | N16: 0 | O16: 0 | P16: 0
B17: Professores Estagiários | C17: =SUM(E17,G17,I17,K17,M17,O17) | D17: =SUM(F17,H17,J17,L17,N17,P17) | E17: 0 | F17: 0 | G17: 0 | H17: 0 | I17: 0 | J17: 0 | K17: 0 | L17: 0 | M17: 0 | N17: 0 | O17: 0 | P17: 0
A18: SUBTOTAL | B18: PRIVADA | C18: =SUM(C15:C17) | D18: =SUM(D15:D17) | E18: =SUM(E15:E17) | F18: =SUM(F15:F17) | G18: =SUM(G15:G17) | H18: =SUM(H15:H17) | I18: =SUM(I15:I17) | J18: =SUM(J15:J17) | ... P18: =SUM(P15:P17)
A19: TOTAL | B19: PRÉ-ESCOLAR | C19: =SUM(C10,C14,C18) | D19: =SUM(D10,D14,D18) | E19: =SUM(E10,E14,E18) | F19: =SUM(F10,F14,F18) | G19: =SUM(G10,G14,G18) | H19: =SUM(H10,H14,H18) | I19: =SUM(I10,I14,I18) | J19: =SUM(J10,J14,J18) | ... P19: =SUM(P10,P14,P18)
A22: TABELA 2.2 – Pessoal Docente no Ensino Primário (Regular, PRAEER, EJA e Especial)
A23: NATUREZA DA ESCOLA | B23: CATEGORIA / FUNÇÃO | C23: TOTAL DE DOCENTES | E23: Mestrado / Doutoramento | G23: Licenciatura em Ensino | I23: Outras Licenciaturas | K23: Bacharelato | M23: Técnico Médio Pedagógico | O23: Outros Técnicos Médios
C24: Total (MF) | D24: Total (F) | E24: MF | F24: F | G24: MF | H24: F | I24: MF | J24: F | K24: MF | L24: F | M24: MF | N24: F | O24: MF | P24: F
A25: PÚBLICA | B25: Educadores / Professores Titulares | C25: =SUM(E25,G25,I25,K25,M25,O25) | D25: =SUM(F25,H25,J25,L25,N25,P25) | E25: 0 | F25: 0 | G25: 0 | H25: 0 | I25: 0 | J25: 0 | K25: 0 | L25: 0 | M25: 0 | N25: 0 | O25: 0 | P25: 0
B26: Professores Coadjuvantes | C26: =SUM(E26,G26,I26,K26,M26,O26) | D26: =SUM(F26,H26,J26,L26,N26,P26) | E26: 0 | F26: 0 | G26: 0 | H26: 0 | I26: 0 | J26: 0 | K26: 0 | L26: 0 | M26: 0 | N26: 0 | O26: 0 | P26: 0
B27: Professores Estagiários | C27: =SUM(E27,G27,I27,K27,M27,O27) | D27: =SUM(F27,H27,J27,L27,N27,P27) | E27: 0 | F27: 0 | G27: 0 | H27: 0 | I27: 0 | J27: 0 | K27: 0 | L27: 0 | M27: 0 | N27: 0 | O27: 0 | P27: 0
A28: SUBTOTAL | B28: PÚBLICA | C28: =SUM(C25:C27) | D28: =SUM(D25:D27) | E28: =SUM(E25:E27) | F28: =SUM(F25:F27) | G28: =SUM(G25:G27) | H28: =SUM(H25:H27) | I28: =SUM(I25:I27) | J28: =SUM(J25:J27) | ... P28: =SUM(P25:P27)
A29: PÚBLICO-PRIVADA | B29: Educadores / Professores Titulares | C29: =SUM(E29,G29,I29,K29,M29,O29) | D29: =SUM(F29,H29,J29,L29,N29,P29) | E29: 0 | F29: 0 | G29: 0 | H29: 0 | I29: 0 | J29: 0 | K29: 0 | L29: 0 | M29: 0 | N29: 0 | O29: 0 | P29: 0
B30: Professores Coadjuvantes | C30: =SUM(E30,G30,I30,K30,M30,O30) | D30: =SUM(F30,H30,J30,L30,N30,P30) | E30: 0 | F30: 0 | G30: 0 | H30: 0 | I30: 0 | J30: 0 | K30: 0 | L30: 0 | M30: 0 | N30: 0 | O30: 0 | P30: 0
B31: Professores Estagiários | C31: =SUM(E31,G31,I31,K31,M31,O31) | D31: =SUM(F31,H31,J31,L31,N31,P31) | E31: 0 | F31: 0 | G31: 0 | H31: 0 | I31: 0 | J31: 0 | K31: 0 | L31: 0 | M31: 0 | N31: 0 | O31: 0 | P31: 0
A32: SUBTOTAL | B32: PÚBLICO-PRIVADA | C32: =SUM(C29:C31) | D32: =SUM(D29:D31) | E32: =SUM(E29:E31) | F32: =SUM(F29:F31) | G32: =SUM(G29:G31) | H32: =SUM(H29:H31) | I32: =SUM(I29:I31) | J32: =SUM(J29:J31) | ... P32: =SUM(P29:P31)
A33: PRIVADA | B33: Educadores / Professores Titulares | C33: =SUM(E33,G33,I33,K33,M33,O33) | D33: =SUM(F33,H33,J33,L33,N33,P33) | E33: 0 | F33: 0 | G33: 0 | H33: 0 | I33: 0 | J33: 0 | K33: 0 | L33: 0 | M33: 0 | N33: 0 | O33: 0 | P33: 0
B34: Professores Coadjuvantes | C34: =SUM(E34,G34,I34,K34,M34,O34) | D34: =SUM(F34,H34,J34,L34,N34,P34) | E34: 0 | F34: 0 | G34: 0 | H34: 0 | I34: 0 | J34: 0 | K34: 0 | L34: 0 | M34: 0 | N34: 0 | O34: 0 | P34: 0
B35: Professores Estagiários | C35: =SUM(E35,G35,I35,K35,M35,O35) | D35: =SUM(F35,H35,J35,L35,N35,P35) | E35: 0 | F35: 0 | G35: 0 | H35: 0 | I35: 0 | J35: 0 | K35: 0 | L35: 0 | M35: 0 | N35: 0 | O35: 0 | P35: 0
A36: SUBTOTAL | B36: PRIVADA | C36: =SUM(C33:C35) | D36: =SUM(D33:D35) | E36: =SUM(E33:E35) | F36: =SUM(F33:F35) | G36: =SUM(G33:G35) | H36: =SUM(H33:H35) | I36: =SUM(I33:I35) | J36: =SUM(J33:J35) | ... P36: =SUM(P33:P35)
A37: TOTAL | B37: ENSINO PRIMÁRIO | C37: =SUM(C28,C32,C36) | D37: =SUM(D28,D32,D36) | E37: =SUM(E28,E32,E36) | F37: =SUM(F28,F32,F36) | G37: =SUM(G28,G32,G36) | H37: =SUM(H28,H32,H36) | I37: =SUM(I28,I32,I36) | J37: =SUM(J28,J32,J36) | ... P37: =SUM(P28,P32,P36)
A40: TABELA 2.3 – Pessoal Docente no Ensino Secundário do I Ciclo
A41: NATUREZA DA ESCOLA | B41: CATEGORIA / FUNÇÃO | C41: TOTAL DE DOCENTES | E41: Mestrado / Doutoramento | G41: Licenciatura em Ensino | I41: Outras Licenciaturas | K41: Bacharelato | M41: Técnico Médio Pedagógico | O41: Outros Técnicos Médios
C42: Total (MF) | D42: Total (F) | E42: MF | F42: F | G42: MF | H42: F | I42: MF | J42: F | K42: MF | L42: F | M42: MF | N42: F | O42: MF | P42: F
A43: PÚBLICA | B43: Educadores / Professores Titulares | C43: =SUM(E43,G43,I43,K43,M43,O43) | D43: =SUM(F43,H43,J43,L43,N43,P43) | E43: 0 | F43: 0 | G43: 0 | H43: 0 | I43: 0 | J43: 0 | K43: 0 | L43: 0 | M43: 0 | N43: 0 | O43: 0 | P43: 0
B44: Professores Coadjuvantes | C44: =SUM(E44,G44,I44,K44,M44,O44) | D44: =SUM(F44,H44,J44,L44,N44,P44) | E44: 0 | F44: 0 | G44: 0 | H44: 0 | I44: 0 | J44: 0 | K44: 0 | L44: 0 | M44: 0 | N44: 0 | O44: 0 | P44: 0
B45: Professores Estagiários | C45: =SUM(E45,G45,I45,K45,M45,O45) | D45: =SUM(F45,H45,J45,L45,N45,P45) | E45: 0 | F45: 0 | G45: 0 | H45: 0 | I45: 0 | J45: 0 | K45: 0 | L45: 0 | M45: 0 | N45: 0 | O45: 0 | P45: 0
A46: SUBTOTAL | B46: PÚBLICA | C46: =SUM(C43:C45) | D46: =SUM(D43:D45) | E46: =SUM(E43:E45) | F46: =SUM(F43:F45) | G46: =SUM(G43:G45) | H46: =SUM(H43:H45) | I46: =SUM(I43:I45) | J46: =SUM(J43:J45) | ... P46: =SUM(P43:P45)
...

Sheet 3 - INFRAESTRUTURAS
A2: SECÇÃO 3 - DADOS ESTATÍSTICOS SOBRE INFRAESTRUTURAS E ESCOLAS EM FUNCIONAMENTO
A4: TABELA 3.1 – Estabelecimentos de Ensino e Salas de Aula em Funcionamento por Tipologia e Natureza
A5: DESIGNAÇÃO / TIPO DE ESCOLA | B5: NATUREZA JURÍDICA | C5: ESCOLAS EM FUNCIONAMENTO | D5: SALAS DE AULA UTILIZADAS | H5: LAVATÓRIOS / SANITÁRIOS | I5: COM ÁGUA | J5: COM ELETRICIDADE | K5: COMPUTADORES | L5: COM INTERNET
D6: Definitivas | E6: Provisórias | F6: Ar Livre / Tendas | G6: TOTAL SALAS
A7: Escola Primária | B7: PÚBLICA | C7: 0 | D7: 0 | E7: 0 | F7: 0 | G7: =SUM(D7:F7) | H7: 0 | I7: 0 | J7: 0 | K7: 0 | L7: 0
B8: PÚBLICO-PRIVADA | C8: 0 | D8: 0 | E8: 0 | F8: 0 | G8: =SUM(D8:F8) | H8: 0 | I8: 0 | J8: 0 | K8: 0 | L8: 0
B9: PRIVADA | C9: 0 | D9: 0 | E9: 0 | F9: 0 | G9: =SUM(D9:F9) | H9: 0 | I9: 0 | J9: 0 | K9: 0 | L9: 0
A10: SUBTOTAL | B10: Escola Primária | C10: =SUM(C7:C9) | D10: =SUM(D7:D9) | E10: =SUM(E7:E9) | F10: =SUM(F7:F9) | G10: =SUM(G7:G9) | H10: =SUM(H7:H9) | I10: =SUM(I7:I9) | J10: =SUM(J7:J9) | ... L10: =SUM(L7:L9)
A11: Colégio | B11: PÚBLICA | C11: 0 | D11: 0 | E11: 0 | F11: 0 | G11: =SUM(D11:F11) | H11: 0 | I11: 0 | J11: 0 | K11: 0 | L11: 0
B12: PÚBLICO-PRIVADA | C12: 0 | D12: 0 | E12: 0 | F12: 0 | G12: =SUM(D12:F12) | H12: 0 | I12: 0 | J12: 0 | K12: 0 | L12: 0
B13: PRIVADA | C13: 0 | D13: 0 | E13: 0 | F13: 0 | G13: =SUM(D13:F13) | H13: 0 | I13: 0 | J13: 0 | K13: 0 | L13: 0
A14: SUBTOTAL | B14: Colégio | C14: =SUM(C11:C13) | D14: =SUM(D11:D13) | E14: =SUM(E11:E13) | F14: =SUM(F11:F13) | G14: =SUM(G11:G13) | H14: =SUM(H11:H13) | I14: =SUM(I11:I13) | J14: =SUM(J11:J13) | ... L14: =SUM(L11:L13)
A15: Escola Secundária do I Ciclo | B15: PÚBLICA | C15: 0 | D15: 0 | E15: 0 | F15: 0 | G15: =SUM(D15:F15) | H15: 0 | I15: 0 | J15: 0 | K15: 0 | L15: 0
B16: PÚBLICO-PRIVADA | C16: 0 | D16: 0 | E16: 0 | F16: 0 | G16: =SUM(D16:F16) | H16: 0 | I16: 0 | J16: 0 | K16: 0 | L16: 0
B17: PRIVADA | C17: 0 | D17: 0 | E17: 0 | F17: 0 | G17: =SUM(D17:F17) | H17: 0 | I17: 0 | J17: 0 | K17: 0 | L17: 0
A18: SUBTOTAL | B18: Escola Secundária do I Ciclo | C18: =SUM(C15:C17) | D18: =SUM(D15:D17) | E18: =SUM(E15:E17) | F18: =SUM(F15:F17) | G18: =SUM(G15:G17) | H18: =SUM(H15:H17) | I18: =SUM(I15:I17) | J18: =SUM(J15:J17) | ... L18: =SUM(L15:L17)
A19: Liceu | B19: PÚBLICA | C19: 0 | D19: 0 | E19: 0 | F19: 0 | G19: =SUM(D19:F19) | H19: 0 | I19: 0 | J19: 0 | K19: 0 | L19: 0
B20: PÚBLICO-PRIVADA | C20: 0 | D20: 0 | E20: 0 | F20: 0 | G20: =SUM(D20:F20) | H20: 0 | I20: 0 | J20: 0 | K20: 0 | L20: 0
B21: PRIVADA | C21: 0 | D21: 0 | E21: 0 | F21: 0 | G21: =SUM(D21:F21) | H21: 0 | I21: 0 | J21: 0 | K21: 0 | L21: 0
A22: SUBTOTAL | B22: Liceu | C22: =SUM(C19:C21) | D22: =SUM(D19:D21) | E22: =SUM(E19:E21) | F22: =SUM(F19:F21) | G22: =SUM(G19:G21) | H22: =SUM(H19:H21) | I22: =SUM(I19:I21) | J22: =SUM(J19:J21) | ... L22: =SUM(L19:L21)
A23: Instituto Politécnico / Técnico | B23: PÚBLICA | C23: 0 | D23: 0 | E23: 0 | F23: 0 | G23: =SUM(D23:F23) | H23: 0 | I23: 0 | J23: 0 | K23: 0 | L23: 0
B24: PÚBLICO-PRIVADA | C24: 0 | D24: 0 | E24: 0 | F24: 0 | G24: =SUM(D24:F24) | H24: 0 | I24: 0 | J24: 0 | K24: 0 | L24: 0
B25: PRIVADA | C25: 0 | D25: 0 | E25: 0 | F25: 0 | G25: =SUM(D25:F25) | H25: 0 | I25: 0 | J25: 0 | K25: 0 | L25: 0
A26: SUBTOTAL | B26: Instituto Politécnico / Técnico | C26: =SUM(C23:C25) | D26: =SUM(D23:D25) | E26: =SUM(E23:E25) | F26: =SUM(F23:F25) | G26: =SUM(G23:G25) | H26: =SUM(H23:H25) | I26: =SUM(I23:I25) | J26: =SUM(J23:J25) | ... L26: =SUM(L23:L25)
A27: Magistério / Instituto Médio Pedagógico | B27: PÚBLICA | C27: 0 | D27: 0 | E27: 0 | F27: 0 | G27: =SUM(D27:F27) | H27: 0 | I27: 0 | J27: 0 | K27: 0 | L27: 0
B28: PÚBLICO-PRIVADA | C28: 0 | D28: 0 | E28: 0 | F28: 0 | G28: =SUM(D28:F28) | H28: 0 | I28: 0 | J28: 0 | K28: 0 | L28: 0
B29: PRIVADA | C29: 0 | D29: 0 | E29: 0 | F29: 0 | G29: =SUM(D29:F29) | H29: 0 | I29: 0 | J29: 0 | K29: 0 | L29: 0
A30: SUBTOTAL | B30: Magistério / Instituto Médio Pedagógico | C30: =SUM(C27:C29) | D30: =SUM(D27:D29) | E30: =SUM(E27:E29) | F30: =SUM(F27:F29) | G30: =SUM(G27:G29) | H30: =SUM(H27:H29) | I30: =SUM(I27:I29) | J30: =SUM(J27:J29) | ... L30: =SUM(L27:L29)
A31: Complexo Escolar (Iniciação ao Primário) | B31: PÚBLICA | C31: 0 | D31: 0 | E31: 0 | F31: 0 | G31: =SUM(D31:F31) | H31: 0 | I31: 0 | J31: 0 | K31: 0 | L31: 0
B32: PÚBLICO-PRIVADA | C32: 0 | D32: 0 | E32: 0 | F32: 0 | G32: =SUM(D32:F32) | H32: 0 | I32: 0 | J32: 0 | K32: 0 | L32: 0
B33: PRIVADA | C33: 0 | D33: 0 | E33: 0 | F33: 0 | G33: =SUM(D33:F33) | H33: 0 | I33: 0 | J33: 0 | K33: 0 | L33: 0
A34: SUBTOTAL | B34: Complexo Escolar (Iniciação ao Primário) | C34: =SUM(C31:C33) | D34: =SUM(D31:D33) | E34: =SUM(E31:E33) | F34: =SUM(F31:F33) | G34: =SUM(G31:G33) | H34: =SUM(H31:H33) | I34: =SUM(I31:I33) | J34: =SUM(J31:J33) | ... L34: =SUM(L31:L33)
A35: Complexo Escolar (Primário e I Ciclo) | B35: PÚBLICA | C35: 0 | D35: 0 | E35: 0 | F35: 0 | G35: =SUM(D35:F35) | H35: 0 | I35: 0 | J35: 0 | K35: 0 | L35: 0
B36: PÚBLICO-PRIVADA | C36: 0 | D36: 0 | E36: 0 | F36: 0 | G36: =SUM(D36:F36) | H36: 0 | I36: 0 | J36: 0 | K36: 0 | L36: 0
B37: PRIVADA | C37: 0 | D37: 0 | E37: 0 | F37: 0 | G37: =SUM(D37:F37) | H37: 0 | I37: 0 | J37: 0 | K37: 0 | L37: 0
A38: SUBTOTAL | B38: Complexo Escolar (Primário e I Ciclo) | C38: =SUM(C35:C37) | D38: =SUM(D35:D37) | E38: =SUM(E35:E37) | F38: =SUM(F35:F37) | G38: =SUM(G35:G37) | H38: =SUM(H35:H37) | I38: =SUM(I35:I37) | J38: =SUM(J35:J37) | ... L38: =SUM(L35:L37)
A39: Complexo Escolar (I e II Ciclo) | B39: PÚBLICA | C39: 0 | D39: 0 | E39: 0 | F39: 0 | G39: =SUM(D39:F39) | H39: 0 | I39: 0 | J39: 0 | K39: 0 | L39: 0
B40: PÚBLICO-PRIVADA | C40: 0 | D40: 0 | E40: 0 | F40: 0 | G40: =SUM(D40:F40) | H40: 0 | I40: 0 | J40: 0 | K40: 0 | L40: 0
B41: PRIVADA | C41: 0 | D41: 0 | E41: 0 | F41: 0 | G41: =SUM(D41:F41) | H41: 0 | I41: 0 | J41: 0 | K41: 0 | L41: 0
A42: SUBTOTAL | B42: Complexo Escolar (I e II Ciclo) | C42: =SUM(C39:C41) | D42: =SUM(D39:D41) | E42: =SUM(E39:E41) | F42: =SUM(F39:F41) | G42: =SUM(G39:G41) | H42: =SUM(H39:H41) | I42: =SUM(I39:I41) | J42: =SUM(J39:J41) | ... L42: =SUM(L39:L41)
...

Sheet 4 - APROVEITAMENTO
A2: SECÇÃO 4 - DADOS ESTATÍSTICOS SOBRE APROVEITAMENTO ESCOLAR
A4: TABELA 4.1 – Rendimento e Aproveitamento Escolar por Nível de Ensino, Classe e Natureza
A5: SUBSISTEMA / NÍVEL | B5: NATUREZA DE ENSINO | C5: CLASSE / ETAPA | D5: ALUNOS MATRICULADOS | F5: ALUNOS APROVADOS | H5: ALUNOS REPROVADOS | J5: ALUNOS DESISTIDOS | L5: VALIDAÇÃO (CONSISTÊNCIA) | N5: DIFERENÇA (RESIDUAL 0 = OK) | P5: INDICADORES (%)
D6: Total (MF) | E6: Total (F) | F6: Total (MF) | G6: Total (F) | H6: Total (MF) | I6: Total (F) | J6: Total (MF) | K6: Total (F) | L6: Validação (MF) | M6: Validação (F) | N6: Residual (MF) | O6: Residual (F) | P6: % Aprovados | Q6: % Desistentes
A7: Educação Pré-Escolar | B7: PÚBLICA | C7: Creche (0-1 ano) - Turno da Manhã | D7: 0 | E7: 0 | F7: 0 | G7: 0 | H7: 0 | I7: 0 | J7: 0 | K7: 0 | L7: =IF(D7=F7+H7+J7,"Correcto","Falso") | M7: =IF(E7=G7+I7+K7,"Correcto","Falso") | N7: =D7-(F7+H7+J7) | O7: =E7-(G7+I7+K7) | P7: =IF(D7>0,F7/D7,0) | Q7: =IF(D7>0,J7/D7,0)
A8: Educação Pré-Escolar | B8: PÚBLICA | C8: Creche (1-2 anos) - Turno da Manhã | D8: 0 | E8: 0 | F8: 0 | G8: 0 | H8: 0 | I8: 0 | J8: 0 | K8: 0 | L8: =IF(D8=F8+H8+J8,"Correcto","Falso") | M8: =IF(E8=G8+I8+K8,"Correcto","Falso") | N8: =D8-(F8+H8+J8) | O8: =E8-(G8+I8+K8) | P8: =IF(D8>0,F8/D8,0) | Q8: =IF(D8>0,J8/D8,0)
A9: Educação Pré-Escolar | B9: PÚBLICA | C9: Jardim de Infância (3 anos) - Turno da Manhã | D9: 0 | E9: 0 | F9: 0 | G9: 0 | H9: 0 | I9: 0 | J9: 0 | K9: 0 | L9: =IF(D9=F9+H9+J9,"Correcto","Falso") | M9: =IF(E9=G9+I9+K9,"Correcto","Falso") | N9: =D9-(F9+H9+J9) | O9: =E9-(G9+I9+K9) | P9: =IF(D9>0,F9/D9,0) | Q9: =IF(D9>0,J9/D9,0)
A10: Educação Pré-Escolar | B10: PÚBLICA | C10: Jardim de Infância (4 anos) - Turno da Manhã | D10: 0 | E10: 0 | F10: 0 | G10: 0 | H10: 0 | I10: 0 | J10: 0 | K10: 0 | L10: =IF(D10=F10+H10+J10,"Correcto","Falso") | M10: =IF(E10=G10+I10+K10,"Correcto","Falso") | N10: =D10-(F10+H10+J10) | O10: =E10-(G10+I10+K10) | P10: =IF(D10>0,F10/D10,0) | Q10: =IF(D10>0,J10/D10,0)
A11: Educação Pré-Escolar | B11: PÚBLICA | C11: Jardim de Infância (5 anos) - Turno da Manhã | D11: 0 | E11: 0 | F11: 0 | G11: 0 | H11: 0 | I11: 0 | J11: 0 | K11: 0 | L11: =IF(D11=F11+H11+J11,"Correcto","Falso") | M11: =IF(E11=G11+I11+K11,"Correcto","Falso") | N11: =D11-(F11+H11+J11) | O11: =E11-(G11+I11+K11) | P11: =IF(D11>0,F11/D11,0) | Q11: =IF(D11>0,J11/D11,0)
A12: Educação Pré-Escolar | B12: PÚBLICA | C12: Iniciação (5 anos) - Turno da Manhã | D12: 0 | E12: 0 | F12: 0 | G12: 0 | H12: 0 | I12: 0 | J12: 0 | K12: 0 | L12: =IF(D12=F12+H12+J12,"Correcto","Falso") | M12: =IF(E12=G12+I12+K12,"Correcto","Falso") | N12: =D12-(F12+H12+J12) | O12: =E12-(G12+I12+K12) | P12: =IF(D12>0,F12/D12,0) | Q12: =IF(D12>0,J12/D12,0)
A13: Educação Pré-Escolar | B13: PÚBLICA | C13: Iniciação (6 anos) - Turno da Manhã | D13: 0 | E13: 0 | F13: 0 | G13: 0 | H13: 0 | I13: 0 | J13: 0 | K13: 0 | L13: =IF(D13=F13+H13+J13,"Correcto","Falso") | M13: =IF(E13=G13+I13+K13,"Correcto","Falso") | N13: =D13-(F13+H13+J13) | O13: =E13-(G13+I13+K13) | P13: =IF(D13>0,F13/D13,0) | Q13: =IF(D13>0,J13/D13,0)
A14: Educação Pré-Escolar | B14: PÚBLICA | C14: Centro Infantil Comunitário (CIC) - Turno da Manhã | D14: 0 | E14: 0 | F14: 0 | G14: 0 | H14: 0 | I14: 0 | J14: 0 | K14: 0 | L14: =IF(D14=F14+H14+J14,"Correcto","Falso") | M14: =IF(E14=G14+I14+K14,"Correcto","Falso") | N14: =D14-(F14+H14+J14) | O14: =E14-(G14+I14+K14) | P14: =IF(D14>0,F14/D14,0) | Q14: =IF(D14>0,J14/D14,0)
A15: Educação Pré-Escolar | B15: PÚBLICO-PRIVADA | C15: Creche (0-1 ano) - Turno da Manhã | D15: 0 | E15: 0 | F15: 0 | G15: 0 | H15: 0 | I15: 0 | J15: 0 | K15: 0 | L15: =IF(D15=F15+H15+J15,"Correcto","Falso") | M15: =IF(E15=G15+I15+K15,"Correcto","Falso") | N15: =D15-(F15+H15+J15) | O15: =E15-(G15+I15+K15) | P15: =IF(D15>0,F15/D15,0) | Q15: =IF(D15>0,J15/D15,0)
A16: Educação Pré-Escolar | B16: PÚBLICO-PRIVADA | C16: Creche (1-2 anos) - Turno da Manhã | D16: 0 | E16: 0 | F16: 0 | G16: 0 | H16: 0 | I16: 0 | J16: 0 | K16: 0 | L16: =IF(D16=F16+H16+J16,"Correcto","Falso") | M16: =IF(E16=G16+I16+K16,"Correcto","Falso") | N16: =D16-(F16+H16+J16) | O16: =E16-(G16+I16+K16) | P16: =IF(D16>0,F16/D16,0) | Q16: =IF(D16>0,J16/D16,0)
A17: Educação Pré-Escolar | B17: PÚBLICO-PRIVADA | C17: Jardim de Infância (3 anos) - Turno da Manhã | D17: 0 | E17: 0 | F17: 0 | G17: 0 | H17: 0 | I17: 0 | J17: 0 | K17: 0 | L17: =IF(D17=F17+H17+J17,"Correcto","Falso") | M17: =IF(E17=G17+I17+K17,"Correcto","Falso") | N17: =D17-(F17+H17+J17) | O17: =E17-(G17+I17+K17) | P17: =IF(D17>0,F17/D17,0) | Q17: =IF(D17>0,J17/D17,0)
A18: Educação Pré-Escolar | B18: PÚBLICO-PRIVADA | C18: Jardim de Infância (4 anos) - Turno da Manhã | D18: 0 | E18: 0 | F18: 0 | G18: 0 | H18: 0 | I18: 0 | J18: 0 | K18: 0 | L18: =IF(D18=F18+H18+J18,"Correcto","Falso") | M18: =IF(E18=G18+I18+K18,"Correcto","Falso") | N18: =D18-(F18+H18+J18) | O18: =E18-(G18+I18+K18) | P18: =IF(D18>0,F18/D18,0) | Q18: =IF(D18>0,J18/D18,0)
... A274: Educação Pré-Escolar | B274: PÚBLICO-PRIVADA | C274: Jardim de Infância (4 anos) - Turno da Manhã | D274: 0 | E274: 0 | F274: 0 | G274: 0 | H274: 0 | I274: 0 | J274: 0 | K274: 0 | L274: =IF(D274=F274+H274+J274,"Correcto","Falso") | M274: =IF(E274=G274+I274+K274,"Correcto","Falso") | N274: =D274-(F274+H274+J274) | O274: =E274-(G274+I274+K274) | P274: =IF(D274>0,F274/D274,0) | Q274: =IF(D274>0,J274/D274,0)
A275: SUBTOTAL | B275: EDUCAÇÃO PRÉ-ESCOLAR | C275: TODAS AS MODALIDADES | D275: =SUM(D7:D274) | E275: =SUM(E7:E274) | F275: =SUM(F7:F274) | G275: =SUM(G7:G274) | H275: =SUM(H7:H274) | I275: =SUM(I7:I274) | J275: =SUM(J7:J274) | K275: =SUM(K7:K274) | L275: =IF(D275=F275+H275+J275,"Correcto","Falso") | M275: =IF(E275=G275+I275+K275,"Correcto","Falso") | N275: =D275-(F275+H275+J275) | O275: =IF(D275>0,F275/D275,0) | P275: =IF(D275>0,J275/D275,0)
A277: Ensino Primário | B277: PÚBLICA | C277: 1ª Classe (Regular) | D277: 0 | E277: 0 | F277: 0 | G277: 0 | H277: 0 | I277: 0 | J277: 0 | K277: 0 | L277: =IF(D277=F277+H277+J277,"Correcto","Falso") | M277: =IF(E277=G277+I277+K277,"Correcto","Falso") | N277: =D277-(F277+H277+J277) | O277: =E277-(G277+I277+K277) | P277: =IF(D277>0,F277/D277,0) | Q277: =IF(D277>0,J277/D277,0)
A278: Ensino Primário | B278: PÚBLICA | C278: 2ª Classe (Regular) | D278: 0 | E278: 0 | F278: 0 | G278: 0 | H278: 0 | I278: 0 | J278: 0 | K278: 0 | L278: =IF(D278=F278+H278+J278,"Correcto","Falso") | M278: =IF(E278=G278+I278+K278,"Correcto","Falso") | N278: =D278-(F278+H278+J278) | O278: =E278-(G278+I278+K278) | P278: =IF(D278>0,F278/D278,0) | Q278: =IF(D278>0,J278/D278,0)
A279: Ensino Primário | B279: PÚBLICA | C279: 3ª Classe (Regular) | D279: 0 | E279: 0 | F279: 0 | G279: 0 | H279: 0 | I279: 0 | J279: 0 | K279: 0 | L279: =IF(D279=F279+H279+J279,"Correcto","Falso") | M279: =IF(E279=G279+I279+K279,"Correcto","Falso") | N279: =D279-(F279+H279+J279) | O279: =E279-(G279+I279+K279) | P279: =IF(D279>0,F279/D279,0) | Q279: =IF(D279>0,J279/D279,0)
A280: Ensino Primário | B280: PÚBLICA | C280: 4ª Classe (Regular) | D280: 0 | E280: 0 | F280: 0 | G280: 0 | H280: 0 | I280: 0 | J280: 0 | K280: 0 | L280: =IF(D280=F280+H280+J280,"Correcto","Falso") | M280: =IF(E280=G280+I280+K280,"Correcto","Falso") | N280: =D280-(F280+H280+J280) | O280: =E280-(G280+I280+K280) | P280: =IF(D280>0,F280/D280,0) | Q280: =IF(D280>0,J280/D280,0)
A281: Ensino Primário | B281: PÚBLICA | C281: 5ª Classe (Regular) | D281: 0 | E281: 0 | F281: 0 | G281: 0 | H281: 0 | I281: 0 | J281: 0 | K281: 0 | L281: =IF(D281=F281+H281+J281,"Correcto","Falso") | M281: =IF(E281=G281+I281+K281,"Correcto","Falso") | N281: =D281-(F281+H281+J281) | O281: =E281-(G281+I281+K281) | P281: =IF(D281>0,F281/D281,0) | Q281: =IF(D281>0,J281/D281,0)
A282: Ensino Primário | B282: PÚBLICA | C282: 6ª Classe (Regular) | D282: 0 | E282: 0 | F282: 0 | G282: 0 | H282: 0 | I282: 0 | J282: 0 | K282: 0 | L282: =IF(D282=F282+H282+J282,"Correcto","Falso") | M282: =IF(E282=G282+I282+K282,"Correcto","Falso") | N282: =D282-(F282+H282+J282) | O282: =E282-(G282+I282+K282) | P282: =IF(D282>0,F282/D282,0) | Q282: =IF(D282>0,J282/D282,0)
A283: Ensino Primário | B283: PÚBLICA | C283: 1ª Classe (PRAEER - Aceleração Escolar) | D283: 0 | E283: 0 | F283: 0 | G283: 0 | H283: 0 | I283: 0 | J283: 0 | K283: 0 | L283: =IF(D283=F283+H283+J283,"Correcto","Falso") | M283: =IF(E283=G283+I283+K283,"Correcto","Falso") | N283: =D283-(F283+H283+J283) | O283: =E283-(G283+I283+K283) | P283: =IF(D283>0,F283/D283,0) | Q283: =IF(D283>0,J283/D283,0)
A284: Ensino Primário | B284: PÚBLICA | C284: 2ª Classe (PRAEER - Aceleração Escolar) | D284: 0 | E284: 0 | F284: 0 | G284: 0 | H284: 0 | I284: 0 | J284: 0 | K284: 0 | L284: =IF(D284=F284+H284+J284,"Correcto","Falso") | M284: =IF(E284=G284+I284+K284,"Correcto","Falso") | N284: =D284-(F284+H284+J284) | O284: =E284-(G284+I284+K284) | P284: =IF(D284>0,F284/D284,0) | Q284: =IF(D284>0,J284/D284,0)
A285: Ensino Primário | B285: PÚBLICA | C285: 3ª Classe (PRAEER - Aceleração Escolar) | D285: 0 | E285: 0 | F285: 0 | G285: 0 | H285: 0 | I285: 0 | J285: 0 | K285: 0 | L285: =IF(D285=F285+H285+J285,"Correcto","Falso") | M285: =IF(E285=G285+I285+K285,"Correcto","Falso") | N285: =D285-(F285+H285+J285) | O285: =E285-(G285+I285+K285) | P285: =IF(D285>0,F285/D285,0) | Q285: =IF(D285>0,J285/D285,0)
A286: Ensino Primário | B286: PÚBLICA | C286: 4ª Classe (PRAEER - Aceleração Escolar) | D286: 0 | E286: 0 | F286: 0 | G286: 0 | H286: 0 | I286: 0 | J286: 0 | K286: 0 | L286: =IF(D286=F286+H286+J286,"Correcto","Falso") | M286: =IF(E286=G286+I286+K286,"Correcto","Falso") | N286: =D286-(F286+H286+J286) | O286: =E286-(G286+I286+K286) | P286: =IF(D286>0,F286/D286,0) | Q286: =IF(D286>0,J286/D286,0)
A287: Ensino Primário | B287: PÚBLICA | C287: 5ª Classe (PRAEER - Aceleração Escolar) | D287: 0 | E287: 0 | F287: 0 | G287: 0 | H287: 0 | I287: 0 | J287: 0 | K287: 0 | L287: =IF(D287=F287+H287+J287,"Correcto","Falso") | M287: =IF(E287=G287+I287+K287,"Correcto","Falso") | N287: =D287-(F287+H287+J287) | O287: =E287-(G287+I287+K287) | P287: =IF(D287>0,F287/D287,0) | Q287: =IF(D287>0,J287/D287,0)
A288: Ensino Primário | B288: PÚBLICA | C288: 6ª Classe (PRAEER - Aceleração Escolar) | D288: 0 | E288: 0 | F288: 0 | G288: 0 | H288: 0 | I288: 0 | J288: 0 | K288: 0 | L288: =IF(D288=F288+H288+J288,"Correcto","Falso") | M288: =IF(E288=G288+I288+K288,"Correcto","Falso") | N288: =D288-(F288+H288+J288) | O288: =E288-(G288+I288+K288) | P288: =IF(D288>0,F288/D288,0) | Q288: =IF(D288>0,J288/D288,0)
... A326: Ensino Primário | B326: PRIVADA | C326: 2ª Classe (EJA - Educação de Adultos) | D326: 0 | E326: 0 | F326: 0 | G326: 0 | H326: 0 | I326: 0 | J326: 0 | K326: 0 | L326: =IF(D326=F326+H326+J326,"Correcto","Falso") | M326: =IF(E326=G326+I326+K326,"Correcto","Falso") | N326: =D326-(F326+H326+J326) | O326: =E326-(G326+I326+K326) | P326: =IF(D326>0,F326/D326,0) | Q326: =IF(D326>0,J326/D326,0)
A327: SUBTOTAL | B327: ENSINO PRIMÁRIO | C327: 1ª À 6ª CLASSE / REGULAR, PRAEER E EJA | D327: =SUM(D277:D326) | E327: =SUM(E277:E326) | F327: =SUM(F277:F326) | G327: =SUM(G277:G326) | H327: =SUM(H277:H326) | I327: =SUM(I277:I326) | J327: =SUM(J277:J326) | K327: =SUM(K277:K326) | L327: =IF(D327=F327+H327+J327,"Correcto","Falso") | M327: =IF(E327=G327+I327+K327,"Correcto","Falso") | N327: =D327-(F327+H327+J327) | O327: =IF(D327>0,F327/D327,0) | P327: =IF(D327>0,J327/D327,0)
A329: I Ciclo Ensino Secundário | B329: PÚBLICA | C329: 7ª Classe - Ensino Secundário Geral | D329: 0 | E329: 0 | F329: 0 | G329: 0 | H329: 0 | I329: 0 | J329: 0 | K329: 0 | L329: =IF(D329=F329+H329+J329,"Correcto","Falso") | M329: =IF(E329=G329+I329+K329,"Correcto","Falso") | N329: =D329-(F329+H329+J329) | O329: =E329-(G329+I329+K329) | P329: =IF(D329>0,F329/D329,0) | Q329: =IF(D329>0,J329/D329,0)
A330: I Ciclo Ensino Secundário | B330: PÚBLICA | C330: 8ª Classe - Ensino Secundário Geral | D330: 0 | E330: 0 | F330: 0 | G330: 0 | H330: 0 | I330: 0 | J330: 0 | K330: 0 | L330: =IF(D330=F330+H330+J330,"Correcto","Falso") | M330: =IF(E330=G330+I330+K330,"Correcto","Falso") | N330: =D330-(F330+H330+J330) | O330: =E330-(G330+I330+K330) | P330: =IF(D330>0,F330/D330,0) | Q330: =IF(D330>0,J330/D330,0)
A331: I Ciclo Ensino Secundário | B331: PÚBLICA | C331: 9ª Classe - Ensino Secundário Geral | D331: 0 | E331: 0 | F331: 0 | G331: 0 | H331: 0 | I331: 0 | J331: 0 | K331: 0 | L331: =IF(D331=F331+H331+J331,"Correcto","Falso") | M331: =IF(E331=G331+I331+K331,"Correcto","Falso") | N331: =D331-(F331+H331+J331) | O331: =E331-(G331+I331+K331) | P331: =IF(D331>0,F331/D331,0) | Q331: =IF(D331>0,J331/D331,0)
A332: I Ciclo Ensino Secundário | B332: PÚBLICA | C332: 7ª Classe - Técnico-Profissional | D332: 0 | E332: 0 | F332: 0 | G332: 0 | H332: 0 | I332: 0 | J332: 0 | K332: 0 | L332: =IF(D332=F332+H332+J332,"Correcto","Falso") | M332: =IF(E332=G332+I332+K332,"Correcto","Falso") | N332: =D332-(F332+H332+J332) | O332: =E332-(G332+I332+K332) | P332: =IF(D332>0,F332/D332,0) | Q332: =IF(D332>0,J332/D332,0)
A333: I Ciclo Ensino Secundário | B333: PÚBLICA | C333: 8ª Classe - Técnico-Profissional | D333: 0 | E333: 0 | F333: 0 | G333: 0 | H333: 0 | I333: 0 | J333: 0 | K333: 0 | L333: =IF(D333=F333+H333+J333,"Correcto","Falso") | M333: =IF(E333=G333+I333+K333,"Correcto","Falso") | N333: =D333-(F333+H333+J333) | O333: =E333-(G333+I333+K333) | P333: =IF(D333>0,F333/D333,0) | Q333: =IF(D333>0,J333/D333,0)
A334: I Ciclo Ensino Secundário | B334: PÚBLICA | C334: 9ª Classe - Técnico-Profissional | D334: 0 | E334: 0 | F334: 0 | G334: 0 | H334: 0 | I334: 0 | J334: 0 | K334: 0 | L334: =IF(D334=F334+H334+J334,"Correcto","Falso") | M334: =IF(E334=G334+I334+K334,"Correcto","Falso") | N334: =D334-(F334+H334+J334) | O334: =E334-(G334+I334+K334) | P334: =IF(D334>0,F334/D334,0) | Q334: =IF(D334>0,J334/D334,0)
A335: I Ciclo Ensino Secundário | B335: PÚBLICA | C335: 7ª Classe - EJA Secundário | D335: 0 | E335: 0 | F335: 0 | G335: 0 | H335: 0 | I335: 0 | J335: 0 | K335: 0 | L335: =IF(D335=F335+H335+J335,"Correcto","Falso") | M335: =IF(E335=G335+I335+K335,"Correcto","Falso") | N335: =D335-(F335+H335+J335) | O335: =E335-(G335+I335+K335) | P335: =IF(D335>0,F335/D335,0) | Q335: =IF(D335>0,J335/D335,0)
A336: I Ciclo Ensino Secundário | B336: PÚBLICA | C336: 8ª Classe - EJA Secundário | D336: 0 | E336: 0 | F336: 0 | G336: 0 | H336: 0 | I336: 0 | J336: 0 | K336: 0 | L336: =IF(D336=F336+H336+J336,"Correcto","Falso") | M336: =IF(E336=G336+I336+K336,"Correcto","Falso") | N336: =D336-(F336+H336+J336) | O336: =E336-(G336+I336+K336) | P336: =IF(D336>0,F336/D336,0) | Q336: =IF(D336>0,J336/D336,0)
...

Sheet 5 - ALUNOS REPETENTES
A2: SECÇÃO 5 - DADOS ESTATÍSTICOS SOBRE ALUNOS REPETENTES
A4: TABELA 5.1 – Alunos Repetentes na Classe de Iniciação (Pré-Escolar)
A5: NATUREZA DE ENSINO | B5: CLASSE / ETAPA | C5: TOTAL REPETENTES | E5: 5 Anos | G5: 6 Anos | I5: Mais de 6 Anos
C6: Total (MF) | D6: Total (F) | E6: MF | F6: F | G6: MF | H6: F | I6: MF | J6: F
A7: PÚBLICA | B7: Iniciação | C7: =SUM(E7,G7,I7) | D7: =SUM(F7,H7,J7) | E7: 0 | F7: 0 | G7: 0 | H7: 0 | I7: 0 | J7: 0
A8: PÚBLICO-PRIVADA | B8: Iniciação | C8: =SUM(E8,G8,I8) | D8: =SUM(F8,H8,J8) | E8: 0 | F8: 0 | G8: 0 | H8: 0 | I8: 0 | J8: 0
A9: PRIVADA | B9: Iniciação | C9: =SUM(E9,G9,I9) | D9: =SUM(F9,H9,J9) | E9: 0 | F9: 0 | G9: 0 | H9: 0 | I9: 0 | J9: 0
A10: TOTAL GERAL | B10: INICIAÇÃO | C10: =SUM(C7:C9) | D10: =SUM(D7:D9) | E10: =SUM(E7:E9) | F10: =SUM(F7:F9) | G10: =SUM(G7:G9) | H10: =SUM(H7:H9) | I10: =SUM(I7:I9) | J10: =SUM(J7:J9)
A12: TABELA 5.2 – Alunos Repetentes no Ensino Primário Regular
A13: NATUREZA DE ENSINO | B13: CLASSE | C13: TOTAL REPETENTES | E13: 6 Anos | G13: 7 Anos | I13: 8 Anos | K13: 9 Anos | M13: 10 Anos | O13: 11 Anos | Q13: 12 Anos | S13: 13 Anos | U13: Mais de 13 Anos
C14: Total (MF) | D14: Total (F) | E14: MF | F14: F | G14: MF | H14: F | I14: MF | J14: F | K14: MF | L14: F | M14: MF | N14: F | O14: MF | P14: F | Q14: MF | R14: F | S14: MF | T14: F | U14: MF | V14: F
A15: PÚBLICA | B15: 1ª Classe | C15: =SUM(E15,G15,I15,K15,M15,O15,Q15,S15,U15) | D15: =SUM(F15,H15,J15,L15,N15,P15,R15,T15,V15) | E15: 0 | F15: 0 | G15: 0 | H15: 0 | I15: 0 | J15: 0 | K15: 0 | L15: 0 | M15: 0 | N15: 0 | O15: 0 | P15: 0 | Q15: 0 | R15: 0 | S15: 0 | T15: 0 | U15: 0 | V15: 0
B16: 2ª Classe | C16: =SUM(E16,G16,I16,K16,M16,O16,Q16,S16,U16) | D16: =SUM(F16,H16,J16,L16,N16,P16,R16,T16,V16) | E16: 0 | F16: 0 | G16: 0 | H16: 0 | I16: 0 | J16: 0 | K16: 0 | L16: 0 | M16: 0 | N16: 0 | O16: 0 | P16: 0 | Q16: 0 | R16: 0 | S16: 0 | T16: 0 | U16: 0 | V16: 0
B17: 3ª Classe | C17: =SUM(E17,G17,I17,K17,M17,O17,Q17,S17,U17) | D17: =SUM(F17,H17,J17,L17,N17,P17,R17,T17,V17) | E17: 0 | F17: 0 | G17: 0 | H17: 0 | I17: 0 | J17: 0 | K17: 0 | L17: 0 | M17: 0 | N17: 0 | O17: 0 | P17: 0 | Q17: 0 | R17: 0 | S17: 0 | T17: 0 | U17: 0 | V17: 0
B18: 4ª Classe | C18: =SUM(E18,G18,I18,K18,M18,O18,Q18,S18,U18) | D18: =SUM(F18,H18,J18,L18,N18,P18,R18,T18,V18) | E18: 0 | F18: 0 | G18: 0 | H18: 0 | I18: 0 | J18: 0 | K18: 0 | L18: 0 | M18: 0 | N18: 0 | O18: 0 | P18: 0 | Q18: 0 | R18: 0 | S18: 0 | T18: 0 | U18: 0 | V18: 0
B19: 5ª Classe | C19: =SUM(E19,G19,I19,K19,M19,O19,Q19,S19,U19) | D19: =SUM(F19,H19,J19,L19,N19,P19,R19,T19,V19) | E19: 0 | F19: 0 | G19: 0 | H19: 0 | I19: 0 | J19: 0 | K19: 0 | L19: 0 | M19: 0 | N19: 0 | O19: 0 | P19: 0 | Q19: 0 | R19: 0 | S19: 0 | T19: 0 | U19: 0 | V19: 0
B20: 6ª Classe | C20: =SUM(E20,G20,I20,K20,M20,O20,Q20,S20,U20) | D20: =SUM(F20,H20,J20,L20,N20,P20,R20,T20,V20) | E20: 0 | F20: 0 | G20: 0 | H20: 0 | I20: 0 | J20: 0 | K20: 0 | L20: 0 | M20: 0 | N20: 0 | O20: 0 | P20: 0 | Q20: 0 | R20: 0 | S20: 0 | T20: 0 | U20: 0 | V20: 0
A21: SUBTOTAL | B21: PÚBLICA | C21: =SUM(C15:C20) | D21: =SUM(D15:D20) | E21: =SUM(E15:E20) | F21: =SUM(F15:F20) | G21: =SUM(G15:G20) | H21: =SUM(H15:H20) | I21: =SUM(I15:I20) | J21: =SUM(J15:J20) | ... V21: =SUM(V15:V20)
A22: PÚBLICO-PRIVADA | B22: 1ª Classe | C22: =SUM(E22,G22,I22,K22,M22,O22,Q22,S22,U22) | D22: =SUM(F22,H22,J22,L22,N22,P22,R22,T22,V22) | E22: 0 | F22: 0 | G22: 0 | H22: 0 | I22: 0 | J22: 0 | K22: 0 | L22: 0 | M22: 0 | N22: 0 | O22: 0 | P22: 0 | Q22: 0 | R22: 0 | S22: 0 | T22: 0 | U22: 0 | V22: 0
B23: 2ª Classe | C23: =SUM(E23,G23,I23,K23,M23,O23,Q23,S23,U23) | D23: =SUM(F23,H23,J23,L23,N23,P23,R23,T23,V23) | E23: 0 | F23: 0 | G23: 0 | H23: 0 | I23: 0 | J23: 0 | K23: 0 | L23: 0 | M23: 0 | N23: 0 | O23: 0 | P23: 0 | Q23: 0 | R23: 0 | S23: 0 | T23: 0 | U23: 0 | V23: 0
B24: 3ª Classe | C24: =SUM(E24,G24,I24,K24,M24,O24,Q24,S24,U24) | D24: =SUM(F24,H24,J24,L24,N24,P24,R24,T24,V24) | E24: 0 | F24: 0 | G24: 0 | H24: 0 | I24: 0 | J24: 0 | K24: 0 | L24: 0 | M24: 0 | N24: 0 | O24: 0 | P24: 0 | Q24: 0 | R24: 0 | S24: 0 | T24: 0 | U24: 0 | V24: 0
B25: 4ª Classe | C25: =SUM(E25,G25,I25,K25,M25,O25,Q25,S25,U25) | D25: =SUM(F25,H25,J25,L25,N25,P25,R25,T25,V25) | E25: 0 | F25: 0 | G25: 0 | H25: 0 | I25: 0 | J25: 0 | K25: 0 | L25: 0 | M25: 0 | N25: 0 | O25: 0 | P25: 0 | Q25: 0 | R25: 0 | S25: 0 | T25: 0 | U25: 0 | V25: 0
B26: 5ª Classe | C26: =SUM(E26,G26,I26,K26,M26,O26,Q26,S26,U26) | D26: =SUM(F26,H26,J26,L26,N26,P26,R26,T26,V26) | E26: 0 | F26: 0 | G26: 0 | H26: 0 | I26: 0 | J26: 0 | K26: 0 | L26: 0 | M26: 0 | N26: 0 | O26: 0 | P26: 0 | Q26: 0 | R26: 0 | S26: 0 | T26: 0 | U26: 0 | V26: 0
B27: 6ª Classe | C27: =SUM(E27,G27,I27,K27,M27,O27,Q27,S27,U27) | D27: =SUM(F27,H27,J27,L27,N27,P27,R27,T27,V27) | E27: 0 | F27: 0 | G27: 0 | H27: 0 | I27: 0 | J27: 0 | K27: 0 | L27: 0 | M27: 0 | N27: 0 | O27: 0 | P27: 0 | Q27: 0 | R27: 0 | S27: 0 | T27: 0 | U27: 0 | V27: 0
A28: SUBTOTAL | B28: PÚBLICO-PRIVADA | C28: =SUM(C22:C27) | D28: =SUM(D22:D27) | E28: =SUM(E22:E27) | F28: =SUM(F22:F27) | G28: =SUM(G22:G27) | H28: =SUM(H22:H27) | I28: =SUM(I22:I27) | J28: =SUM(J22:J27) | ... V28: =SUM(V22:V27)
A29: PRIVADA | B29: 1ª Classe | C29: =SUM(E29,G29,I29,K29,M29,O29,Q29,S29,U29) | D29: =SUM(F29,H29,J29,L29,N29,P29,R29,T29,V29) | E29: 0 | F29: 0 | G29: 0 | H29: 0 | I29: 0 | J29: 0 | K29: 0 | L29: 0 | M29: 0 | N29: 0 | O29: 0 | P29: 0 | Q29: 0 | R29: 0 | S29: 0 | T29: 0 | U29: 0 | V29: 0
B30: 2ª Classe | C30: =SUM(E30,G30,I30,K30,M30,O30,Q30,S30,U30) | D30: =SUM(F30,H30,J30,L30,N30,P30,R30,T30,V30) | E30: 0 | F30: 0 | G30: 0 | H30: 0 | I30: 0 | J30: 0 | K30: 0 | L30: 0 | M30: 0 | N30: 0 | O30: 0 | P30: 0 | Q30: 0 | R30: 0 | S30: 0 | T30: 0 | U30: 0 | V30: 0
B31: 3ª Classe | C31: =SUM(E31,G31,I31,K31,M31,O31,Q31,S31,U31) | D31: =SUM(F31,H31,J31,L31,N31,P31,R31,T31,V31) | E31: 0 | F31: 0 | G31: 0 | H31: 0 | I31: 0 | J31: 0 | K31: 0 | L31: 0 | M31: 0 | N31: 0 | O31: 0 | P31: 0 | Q31: 0 | R31: 0 | S31: 0 | T31: 0 | U31: 0 | V31: 0
B32: 4ª Classe | C32: =SUM(E32,G32,I32,K32,M32,O32,Q32,S32,U32) | D32: =SUM(F32,H32,J32,L32,N32,P32,R32,T32,V32) | E32: 0 | F32: 0 | G32: 0 | H32: 0 | I32: 0 | J32: 0 | K32: 0 | L32: 0 | M32: 0 | N32: 0 | O32: 0 | P32: 0 | Q32: 0 | R32: 0 | S32: 0 | T32: 0 | U32: 0 | V32: 0
B33: 5ª Classe | C33: =SUM(E33,G33,I33,K33,M33,O33,Q33,S33,U33) | D33: =SUM(F33,H33,J33,L33,N33,P33,R33,T33,V33) | E33: 0 | F33: 0 | G33: 0 | H33: 0 | I33: 0 | J33: 0 | K33: 0 | L33: 0 | M33: 0 | N33: 0 | O33: 0 | P33: 0 | Q33: 0 | R33: 0 | S33: 0 | T33: 0 | U33: 0 | V33: 0
B34: 6ª Classe | C34: =SUM(E34,G34,I34,K34,M34,O34,Q34,S34,U34) | D34: =SUM(F34,H34,J34,L34,N34,P34,R34,T34,V34) | E34: 0 | F34: 0 | G34: 0 | H34: 0 | I34: 0 | J34: 0 | K34: 0 | L34: 0 | M34: 0 | N34: 0 | O34: 0 | P34: 0 | Q34: 0 | R34: 0 | S34: 0 | T34: 0 | U34: 0 | V34: 0
A35: SUBTOTAL | B35: PRIVADA | C35: =SUM(C29:C34) | D35: =SUM(D29:D34) | E35: =SUM(E29:E34) | F35: =SUM(F29:F34) | G35: =SUM(G29:G34) | H35: =SUM(H29:H34) | I35: =SUM(I29:I34) | J35: =SUM(J29:J34) | ... V35: =SUM(V29:V34)
A36: TOTAL GERAL | B36: ENSINO PRIMÁRIO | C36: =SUM(C21,C28,C35) | D36: =SUM(D21,D28,D35) | E36: =SUM(E21,E28,E35) | F36: =SUM(F21,F28,F35) | G36: =SUM(G21,G28,G35) | H36: =SUM(H21,H28,H35) | I36: =SUM(I21,I28,I35) | J36: =SUM(J21,J28,J35) | ... V36: =SUM(V21,V28,V35)
A38: TABELA 5.3 – Alunos Repetentes no PRAEER (Aceleração Escolar)
A39: NATUREZA DE ENSINO | B39: ETAPA / MÓDULO | C39: TOTAL REPETENTES | E39: 6 Anos | G39: 7 Anos | I39: 8 Anos | K39: 9 Anos | M39: 10 Anos | O39: 11 Anos | Q39: 12 Anos | S39: 13 Anos | U39: Mais de 13 Anos
C40: Total (MF) | D40: Total (F) | E40: MF | F40: F | G40: MF | H40: F | I40: MF | J40: F | K40: MF | L40: F | M40: MF | N40: F | O40: MF | P40: F | Q40: MF | R40: F | S40: MF | T40: F | U40: MF | V40: F
A41: PÚBLICA | B41: Etapa 1 | C41: =SUM(E41,G41,I41,K41,M41,O41,Q41,S41,U41) | D41: =SUM(F41,H41,J41,L41,N41,P41,R41,T41,V41) | E41: 0 | F41: 0 | G41: 0 | H41: 0 | I41: 0 | J41: 0 | K41: 0 | L41: 0 | M41: 0 | N41: 0 | O41: 0 | P41: 0 | Q41: 0 | R41: 0 | S41: 0 | T41: 0 | U41: 0 | V41: 0
A42: PÚBLICA | B42: Etapa 2 | C42: =SUM(E42,G42,I42,K42,M42,O42,Q42,S42,U42) | D42: =SUM(F42,H42,J42,L42,N42,P42,R42,T42,V42) | E42: 0 | F42: 0 | G42: 0 | H42: 0 | I42: 0 | J42: 0 | K42: 0 | L42: 0 | M42: 0 | N42: 0 | O42: 0 | P42: 0 | Q42: 0 | R42: 0 | S42: 0 | T42: 0 | U42: 0 | V42: 0
A43: PÚBLICA | B43: Etapa 3 | C43: =SUM(E43,G43,I43,K43,M43,O43,Q43,S43,U43) | D43: =SUM(F43,H43,J43,L43,N43,P43,R43,T43,V43) | E43: 0 | F43: 0 | G43: 0 | H43: 0 | I43: 0 | J43: 0 | K43: 0 | L43: 0 | M43: 0 | N43: 0 | O43: 0 | P43: 0 | Q43: 0 | R43: 0 | S43: 0 | T43: 0 | U43: 0 | V43: 0
A44: PÚBLICO-PRIVADA | B44: Etapa 1 | C44: =SUM(E44,G44,I44,K44,M44,O44,Q44,S44,U44) | D44: =SUM(F44,H44,J44,L44,N44,P44,R44,T44,V44) | E44: 0 | F44: 0 | G44: 0 | H44: 0 | I44: 0 | J44: 0 | K44: 0 | L44: 0 | M44: 0 | N44: 0 | O44: 0 | P44: 0 | Q44: 0 | R44: 0 | S44: 0 | T44: 0 | U44: 0 | V44: 0
...

Sheet 6 - NECESSIDADES EDUCATIVA ESPE
A2: SECÇÃO 6 - ALUNOS COM NECESSIDADES EDUCATIVAS ESPECIAIS (NEE)
A4: TABELA 6.1 – NEE na Classe de Iniciação
A5: NATUREZA DA ESCOLA | B5: NÍVEL / ETAPA | C5: TOTAL NEE | E5: Visual | G5: Auditiva | I5: Físico-Motora | K5: Intelectual | M5: Espectro Autista | O5: Outras NEE
C6: Total (MF) | D6: Total (F) | E6: MF | F6: F | G6: MF | H6: F | I6: MF | J6: F | K6: MF | L6: F | M6: MF | N6: F | O6: MF | P6: F
A7: PÚBLICA | B7: Iniciação | C7: =SUM(E7,G7,I7,K7,M7,O7) | D7: =SUM(F7,H7,J7,L7,N7,P7) | E7: 0 | F7: 0 | G7: 0 | H7: 0 | I7: 0 | J7: 0 | K7: 0 | L7: 0 | M7: 0 | N7: 0 | O7: 0 | P7: 0
A8: PÚBLICO-PRIVADA | B8: Iniciação | C8: =SUM(E8,G8,I8,K8,M8,O8) | D8: =SUM(F8,H8,J8,L8,N8,P8) | E8: 0 | F8: 0 | G8: 0 | H8: 0 | I8: 0 | J8: 0 | K8: 0 | L8: 0 | M8: 0 | N8: 0 | O8: 0 | P8: 0
A9: PRIVADA | B9: Iniciação | C9: =SUM(E9,G9,I9,K9,M9,O9) | D9: =SUM(F9,H9,J9,L9,N9,P9) | E9: 0 | F9: 0 | G9: 0 | H9: 0 | I9: 0 | J9: 0 | K9: 0 | L9: 0 | M9: 0 | N9: 0 | O9: 0 | P9: 0
A10: TOTAL | B10: Iniciação | C10: =SUM(C7:C9) | D10: =SUM(D7:D9) | E10: =SUM(E7:E9) | F10: =SUM(F7:F9) | G10: =SUM(G7:G9) | H10: =SUM(H7:H9) | I10: =SUM(I7:I9) | J10: =SUM(J7:J9) | ... P10: =SUM(P7:P9)
A13: TABELA 6.2 – NEE no Ensino Primário Regular
A14: NATUREZA DA ESCOLA | B14: NÍVEL / ETAPA | C14: TOTAL NEE | E14: Visual | G14: Auditiva | I14: Físico-Motora | K14: Intelectual | M14: Espectro Autista | O14: Outras NEE
C15: Total (MF) | D15: Total (F) | E15: MF | F15: F | G15: MF | H15: F | I15: MF | J15: F | K15: MF | L15: F | M15: MF | N15: F | O15: MF | P15: F
A16: PÚBLICA | B16: Ensino Primário | C16: =SUM(E16,G16,I16,K16,M16,O16) | D16: =SUM(F16,H16,J16,L16,N16,P16) | E16: 0 | F16: 0 | G16: 0 | H16: 0 | I16: 0 | J16: 0 | K16: 0 | L16: 0 | M16: 0 | N16: 0 | O16: 0 | P16: 0
A17: PÚBLICO-PRIVADA | B17: Ensino Primário | C17: =SUM(E17,G17,I17,K17,M17,O17) | D17: =SUM(F17,H17,J17,L17,N17,P17) | E17: 0 | F17: 0 | G17: 0 | H17: 0 | I17: 0 | J17: 0 | K17: 0 | L17: 0 | M17: 0 | N17: 0 | O17: 0 | P17: 0
A18: PRIVADA | B18: Ensino Primário | C18: =SUM(E18,G18,I18,K18,M18,O18) | D18: =SUM(F18,H18,J18,L18,N18,P18) | E18: 0 | F18: 0 | G18: 0 | H18: 0 | I18: 0 | J18: 0 | K18: 0 | L18: 0 | M18: 0 | N18: 0 | O18: 0 | P18: 0
A19: TOTAL | B19: Ensino Primário | C19: =SUM(C16:C18) | D19: =SUM(D16:D18) | E19: =SUM(E16:E18) | F19: =SUM(F16:F18) | G19: =SUM(G16:G18) | H19: =SUM(H16:H18) | I19: =SUM(I16:I18) | J19: =SUM(J16:J18) | ... P19: =SUM(P16:P18)
A22: TABELA 6.3 – NEE no PRAEER
A23: NATUREZA DA ESCOLA | B23: NÍVEL / ETAPA | C23: TOTAL NEE | E23: Visual | G23: Auditiva | I23: Físico-Motora | K23: Intelectual | M23: Espectro Autista | O23: Outras NEE
C24: Total (MF) | D24: Total (F) | E24: MF | F24: F | G24: MF | H24: F | I24: MF | J24: F | K24: MF | L24: F | M24: MF | N24: F | O24: MF | P24: F
A25: PÚBLICA | B25: PRAEER | C25: =SUM(E25,G25,I25,K25,M25,O25) | D25: =SUM(F25,H25,J25,L25,N25,P25) | E25: 0 | F25: 0 | G25: 0 | H25: 0 | I25: 0 | J25: 0 | K25: 0 | L25: 0 | M25: 0 | N25: 0 | O25: 0 | P25: 0
A26: PÚBLICO-PRIVADA | B26: PRAEER | C26: =SUM(E26,G26,I26,K26,M26,O26) | D26: =SUM(F26,H26,J26,L26,N26,P26) | E26: 0 | F26: 0 | G26: 0 | H26: 0 | I26: 0 | J26: 0 | K26: 0 | L26: 0 | M26: 0 | N26: 0 | O26: 0 | P26: 0
A27: PRIVADA | B27: PRAEER | C27: =SUM(E27,G27,I27,K27,M27,O27) | D27: =SUM(F27,H27,J27,L27,N27,P27) | E27: 0 | F27: 0 | G27: 0 | H27: 0 | I27: 0 | J27: 0 | K27: 0 | L27: 0 | M27: 0 | N27: 0 | O27: 0 | P27: 0
A28: TOTAL | B28: PRAEER | C28: =SUM(C25:C27) | D28: =SUM(D25:D27) | E28: =SUM(E25:E27) | F28: =SUM(F25:F27) | G28: =SUM(G25:G27) | H28: =SUM(H25:H27) | I28: =SUM(I25:I27) | J28: =SUM(J25:J27) | ... P28: =SUM(P25:P27)
A31: TABELA 6.4 – NEE na EJA - Ensino Primário
A32: NATUREZA DA ESCOLA | B32: NÍVEL / ETAPA | C32: TOTAL NEE | E32: Visual | G32: Auditiva | I32: Físico-Motora | K32: Intelectual | M32: Espectro Autista | O32: Outras NEE
C33: Total (MF) | D33: Total (F) | E33: MF | F33: F | G33: MF | H33: F | I33: MF | J33: F | K33: MF | L33: F | M33: MF | N33: F | O33: MF | P33: F
A34: PÚBLICA | B34: EJA Primário | C34: =SUM(E34,G34,I34,K34,M34,O34) | D34: =SUM(F34,H34,J34,L34,N34,P34) | E34: 0 | F34: 0 | G34: 0 | H34: 0 | I34: 0 | J34: 0 | K34: 0 | L34: 0 | M34: 0 | N34: 0 | O34: 0 | P34: 0
A35: PÚBLICO-PRIVADA | B35: EJA Primário | C35: =SUM(E35,G35,I35,K35,M35,O35) | D35: =SUM(F35,H35,J35,L35,N35,P35) | E35: 0 | F35: 0 | G35: 0 | H35: 0 | I35: 0 | J35: 0 | K35: 0 | L35: 0 | M35: 0 | N35: 0 | O35: 0 | P35: 0
A36: PRIVADA | B36: EJA Primário | C36: =SUM(E36,G36,I36,K36,M36,O36) | D36: =SUM(F36,H36,J36,L36,N36,P36) | E36: 0 | F36: 0 | G36: 0 | H36: 0 | I36: 0 | J36: 0 | K36: 0 | L36: 0 | M36: 0 | N36: 0 | O36: 0 | P36: 0
A37: TOTAL | B37: EJA Primário | C37: =SUM(C34:C36) | D37: =SUM(D34:D36) | E37: =SUM(E34:E36) | F37: =SUM(F34:F36) | G37: =SUM(G34:G36) | H37: =SUM(H34:H36) | I37: =SUM(I34:I36) | J37: =SUM(J34:J36) | ... P37: =SUM(P34:P36)
A40: TABELA 6.5 – NEE no I Ciclo Geral Regular
A41: NATUREZA DA ESCOLA | B41: NÍVEL / ETAPA | C41: TOTAL NEE | E41: Visual | G41: Auditiva | I41: Físico-Motora | K41: Intelectual | M41: Espectro Autista | O41: Outras NEE
C42: Total (MF) | D42: Total (F) | E42: MF | F42: F | G42: MF | H42: F | I42: MF | J42: F | K42: MF | L42: F | M42: MF | N42: F | O42: MF | P42: F
A43: PÚBLICA | B43: I Ciclo Geral | C43: =SUM(E43,G43,I43,K43,M43,O43) | D43: =SUM(F43,H43,J43,L43,N43,P43) | E43: 0 | F43: 0 | G43: 0 | H43: 0 | I43: 0 | J43: 0 | K43: 0 | L43: 0 | M43: 0 | N43: 0 | O43: 0 | P43: 0
A44: PÚBLICO-PRIVADA | B44: I Ciclo Geral | C44: =SUM(E44,G44,I44,K44,M44,O44) | D44: =SUM(F44,H44,J44,L44,N44,P44) | E44: 0 | F44: 0 | G44: 0 | H44: 0 | I44: 0 | J44: 0 | K44: 0 | L44: 0 | M44: 0 | N44: 0 | O44: 0 | P44: 0
A45: PRIVADA | B45: I Ciclo Geral | C45: =SUM(E45,G45,I45,K45,M45,O45) | D45: =SUM(F45,H45,J45,L45,N45,P45) | E45: 0 | F45: 0 | G45: 0 | H45: 0 | I45: 0 | J45: 0 | K45: 0 | L45: 0 | M45: 0 | N45: 0 | O45: 0 | P45: 0
A46: TOTAL | B46: I Ciclo Geral | C46: =SUM(C43:C45) | D46: =SUM(D43:D45) | E46: =SUM(E43:E45) | F46: =SUM(F43:F45) | G46: =SUM(G43:G45) | H46: =SUM(H43:H45) | I46: =SUM(I43:I45) | J46: =SUM(J43:J45) | ... P46: =SUM(P43:P45)
A49: TABELA 6.6 – NEE no I Ciclo Técnico-Profissional
A50: NATUREZA DA ESCOLA | B50: NÍVEL / ETAPA | C50: TOTAL NEE | E50: Visual | G50: Auditiva | I50: Físico-Motora | K50: Intelectual | M50: Espectro Autista | O50: Outras NEE
C51: Total (MF) | D51: Total (F) | E51: MF | F51: F | G51: MF | H51: F | I51: MF | J51: F | K51: MF | L51: F | M51: MF | N51: F | O51: MF | P51: F
A52: PÚBLICA | B52: I Ciclo Técnico | C52: =SUM(E52,G52,I52,K52,M52,O52) | D52: =SUM(F52,H52,J52,L52,N52,P52) | E52: 0 | F52: 0 | G52: 0 | H52: 0 | I52: 0 | J52: 0 | K52: 0 | L52: 0 | M52: 0 | N52: 0 | O52: 0 | P52: 0
...

Sheet 7 - PESSOAL_NAO_DOCENTE
A2: SECÇÃO 7 - DADOS ESTATÍSTICOS SOBRE PESSOAL NÃO DOCENTE, ADMINISTRATIVO E AUXILIAR
A4: TABELA 7.1 – Pessoal nas Creches, Jardins de Infância e Centros Infantis
A5: ESTABELECIMENTO | B5: NATUREZA | C5: TOTAL GERAL | E5: Educadores de Infância | G5: Auxiliares de Acção Educativa | I5: Secretárias | K5: Auxiliares de Limpeza | M5: Guardas | O5: Vigilantes de Saúde / Outros
C6: Total (MF) | D6: Total (F) | E6: MF | F6: F | G6: MF | H6: F | I6: MF | J6: F | K6: MF | L6: F | M6: MF | N6: F | O6: MF | P6: F
A7: Centros Infantis e Jardins | B7: PÚBLICA | C7: =SUM(E7,G7,I7,K7,M7,O7) | D7: =SUM(F7,H7,J7,L7,N7,P7) | E7: 0 | F7: 0 | G7: 0 | H7: 0 | I7: 0 | J7: 0 | K7: 0 | L7: 0 | M7: 0 | N7: 0 | O7: 0 | P7: 0
B8: PÚBLICO-PRIVADA | C8: =SUM(E8,G8,I8,K8,M8,O8) | D8: =SUM(F8,H8,J8,L8,N8,P8) | E8: 0 | F8: 0 | G8: 0 | H8: 0 | I8: 0 | J8: 0 | K8: 0 | L8: 0 | M8: 0 | N8: 0 | O8: 0 | P8: 0
B9: PRIVADA | C9: =SUM(E9,G9,I9,K9,M9,O9) | D9: =SUM(F9,H9,J9,L9,N9,P9) | E9: 0 | F9: 0 | G9: 0 | H9: 0 | I9: 0 | J9: 0 | K9: 0 | L9: 0 | M9: 0 | N9: 0 | O9: 0 | P9: 0
A10: TOTAL | B10: PRÉ-ESCOLAR | C10: =SUM(C7:C9) | D10: =SUM(D7:D9) | E10: =SUM(E7:E9) | F10: =SUM(F7:F9) | G10: =SUM(G7:G9) | H10: =SUM(H7:H9) | I10: =SUM(I7:I9) | J10: =SUM(J7:J9) | ... P10: =SUM(P7:P9)
A13: TABELA 7.2 – Pessoal Administrativo e Auxiliar por Tipo de Escola e Natureza
A14: TIPO DE ESCOLA | B14: NATUREZA | C14: TOTAL PESSOAL | E14: Docentes Administrativos | G14: Técnicos Administrativos / Secretárias | I14: Guardas / Segurança | K14: Pessoal de Limpeza | M14: Outros Auxiliares
C15: Total (MF) | D15: Total (F) | E15: MF | F15: F | G15: MF | H15: F | I15: MF | J15: F | K15: MF | L15: F | M15: MF | N15: F
A16: Escolas Primárias | B16: PÚBLICA | C16: =SUM(E16,G16,I16,K16,M16) | D16: =SUM(F16,H16,J16,L16,N16) | E16: 0 | F16: 0 | G16: 0 | H16: 0 | I16: 0 | J16: 0 | K16: 0 | L16: 0 | M16: 0 | N16: 0
B17: PÚBLICO-PRIVADA | C17: =SUM(E17,G17,I17,K17,M17) | D17: =SUM(F17,H17,J17,L17,N17) | E17: 0 | F17: 0 | G17: 0 | H17: 0 | I17: 0 | J17: 0 | K17: 0 | L17: 0 | M17: 0 | N17: 0
B18: PRIVADA | C18: =SUM(E18,G18,I18,K18,M18) | D18: =SUM(F18,H18,J18,L18,N18) | E18: 0 | F18: 0 | G18: 0 | H18: 0 | I18: 0 | J18: 0 | K18: 0 | L18: 0 | M18: 0 | N18: 0
A19: SUBTOTAL | B19: Escolas Primárias | C19: =SUM(C16:C18) | D19: =SUM(D16:D18) | E19: =SUM(E16:E18) | F19: =SUM(F16:F18) | G19: =SUM(G16:G18) | H19: =SUM(H16:H18) | I19: =SUM(I16:I18) | J19: =SUM(J16:J18) | ... N19: =SUM(N16:N18)
A20: Colégios | B20: PÚBLICA | C20: =SUM(E20,G20,I20,K20,M20) | D20: =SUM(F20,H20,J20,L20,N20) | E20: 0 | F20: 0 | G20: 0 | H20: 0 | I20: 0 | J20: 0 | K20: 0 | L20: 0 | M20: 0 | N20: 0
B21: PÚBLICO-PRIVADA | C21: =SUM(E21,G21,I21,K21,M21) | D21: =SUM(F21,H21,J21,L21,N21) | E21: 0 | F21: 0 | G21: 0 | H21: 0 | I21: 0 | J21: 0 | K21: 0 | L21: 0 | M21: 0 | N21: 0
B22: PRIVADA | C22: =SUM(E22,G22,I22,K22,M22) | D22: =SUM(F22,H22,J22,L22,N22) | E22: 0 | F22: 0 | G22: 0 | H22: 0 | I22: 0 | J22: 0 | K22: 0 | L22: 0 | M22: 0 | N22: 0
A23: SUBTOTAL | B23: Colégios | C23: =SUM(C20:C22) | D23: =SUM(D20:D22) | E23: =SUM(E20:E22) | F23: =SUM(F20:F22) | G23: =SUM(G20:G22) | H23: =SUM(H20:H22) | I23: =SUM(I20:I22) | J23: =SUM(J20:J22) | ... N23: =SUM(N20:N22)
A24: Escolas Técnicas | B24: PÚBLICA | C24: =SUM(E24,G24,I24,K24,M24) | D24: =SUM(F24,H24,J24,L24,N24) | E24: 0 | F24: 0 | G24: 0 | H24: 0 | I24: 0 | J24: 0 | K24: 0 | L24: 0 | M24: 0 | N24: 0
B25: PÚBLICO-PRIVADA | C25: =SUM(E25,G25,I25,K25,M25) | D25: =SUM(F25,H25,J25,L25,N25) | E25: 0 | F25: 0 | G25: 0 | H25: 0 | I25: 0 | J25: 0 | K25: 0 | L25: 0 | M25: 0 | N25: 0
B26: PRIVADA | C26: =SUM(E26,G26,I26,K26,M26) | D26: =SUM(F26,H26,J26,L26,N26) | E26: 0 | F26: 0 | G26: 0 | H26: 0 | I26: 0 | J26: 0 | K26: 0 | L26: 0 | M26: 0 | N26: 0
A27: SUBTOTAL | B27: Escolas Técnicas | C27: =SUM(C24:C26) | D27: =SUM(D24:D26) | E27: =SUM(E24:E26) | F27: =SUM(F24:F26) | G27: =SUM(G24:G26) | H27: =SUM(H24:H26) | I27: =SUM(I24:I26) | J27: =SUM(J24:J26) | ... N27: =SUM(N24:N26)
A28: Liceus | B28: PÚBLICA | C28: =SUM(E28,G28,I28,K28,M28) | D28: =SUM(F28,H28,J28,L28,N28) | E28: 0 | F28: 0 | G28: 0 | H28: 0 | I28: 0 | J28: 0 | K28: 0 | L28: 0 | M28: 0 | N28: 0
B29: PÚBLICO-PRIVADA | C29: =SUM(E29,G29,I29,K29,M29) | D29: =SUM(F29,H29,J29,L29,N29) | E29: 0 | F29: 0 | G29: 0 | H29: 0 | I29: 0 | J29: 0 | K29: 0 | L29: 0 | M29: 0 | N29: 0
B30: PRIVADA | C30: =SUM(E30,G30,I30,K30,M30) | D30: =SUM(F30,H30,J30,L30,N30) | E30: 0 | F30: 0 | G30: 0 | H30: 0 | I30: 0 | J30: 0 | K30: 0 | L30: 0 | M30: 0 | N30: 0
A31: SUBTOTAL | B31: Liceus | C31: =SUM(C28:C30) | D31: =SUM(D28:D30) | E31: =SUM(E28:E30) | F31: =SUM(F28:F30) | G31: =SUM(G28:G30) | H31: =SUM(H28:H30) | I31: =SUM(I28:I30) | J31: =SUM(J28:J30) | ... N31: =SUM(N28:N30)
A32: Institutos Politécnicos | B32: PÚBLICA | C32: =SUM(E32,G32,I32,K32,M32) | D32: =SUM(F32,H32,J32,L32,N32) | E32: 0 | F32: 0 | G32: 0 | H32: 0 | I32: 0 | J32: 0 | K32: 0 | L32: 0 | M32: 0 | N32: 0
B33: PÚBLICO-PRIVADA | C33: =SUM(E33,G33,I33,K33,M33) | D33: =SUM(F33,H33,J33,L33,N33) | E33: 0 | F33: 0 | G33: 0 | H33: 0 | I33: 0 | J33: 0 | K33: 0 | L33: 0 | M33: 0 | N33: 0
B34: PRIVADA | C34: =SUM(E34,G34,I34,K34,M34) | D34: =SUM(F34,H34,J34,L34,N34) | E34: 0 | F34: 0 | G34: 0 | H34: 0 | I34: 0 | J34: 0 | K34: 0 | L34: 0 | M34: 0 | N34: 0
A35: SUBTOTAL | B35: Institutos Politécnicos | C35: =SUM(C32:C34) | D35: =SUM(D32:D34) | E35: =SUM(E32:E34) | F35: =SUM(F32:F34) | G35: =SUM(G32:G34) | H35: =SUM(H32:H34) | I35: =SUM(I32:I34) | J35: =SUM(J32:J34) | ... N35: =SUM(N32:N34)
A36: Magistérios | B36: PÚBLICA | C36: =SUM(E36,G36,I36,K36,M36) | D36: =SUM(F36,H36,J36,L36,N36) | E36: 0 | F36: 0 | G36: 0 | H36: 0 | I36: 0 | J36: 0 | K36: 0 | L36: 0 | M36: 0 | N36: 0
B37: PÚBLICO-PRIVADA | C37: =SUM(E37,G37,I37,K37,M37) | D37: =SUM(F37,H37,J37,L37,N37) | E37: 0 | F37: 0 | G37: 0 | H37: 0 | I37: 0 | J37: 0 | K37: 0 | L37: 0 | M37: 0 | N37: 0
